<!-- UGV_V2_urdf.xml
     created by  Alireza Hekmati
     created at  AIS
     last mod'd  August 8, 2017
     
     this is the urdf file for testing the base only -->

<robot name="UGV">
    <link name="base_footprint">
        <visual>
            <origin xyz="-0.138 0 .275" rpy="0 0 0" />
            <geometry>
                <box size="0.800 0.660 0.270"/>
            </geometry>
            <material name = "grey">
                <color rgba="0.5 0.5 0.5 1"/>
            </material>
        </visual>
    </link>

    <link name="base_link">
        <visual>
            <origin xyz="-0.138 0 .275" rpy="0 0 0" />
            <geometry>
                <box size="0.800 0.660 0.270"/>
            </geometry>
            <material name = "grey">
                <color rgba="0.5 0.5 0.5 1"/>
            </material>
        </visual>
    </link>

    <joint name="joint10" type="fixed">
        <parent link="base_link"/>
        <child link="base_footprint"/>
        <origin rpy="0 0 0" xyz= "0 0 0"/>
    </joint>

    <link name="wheel_right">
        <visual>
        <geometry>
            <cylinder radius="0.1315" length=".070"/>
        </geometry>
        <material name = "black">
            <color rgba="0.2 0.2 0.2 1"/>
        </material>
        </visual>
    </link>

    <joint name="joint1" type="fixed">
        <parent link="base_footprint"/>
        <child link="wheel_right"/>
        <origin rpy="0 1.57075 1.57075" xyz= "0 0.33 0.1315" />
    </joint>

    <link name="wheel_left">
        <visual>
            <geometry>
                <cylinder radius="0.1315" length=".070"/>
            </geometry>
            <material name = "black"/>
        </visual>
    </link>


    <joint name="joint2" type="fixed">
        <parent link="base_footprint"/>
        <child link="wheel_left"/>
        <origin rpy="0 1.57075 1.57075" xyz= "0 -.330 0.1315"/>
    </joint>

    <link name="wheel_small_right">
        <visual>
            <geometry>
                <cylinder radius="0.080" length=".035"/>
            </geometry>
            <material name = "black">
                <color rgba="0 0 0 1"/>
            </material>
        </visual>
    </link>

    <joint name="joint3" type="fixed">
        <parent link="base_footprint"/>
        <child link="wheel_small_right"/>
        <origin rpy="0 1.57075 1.57075" xyz= "-0.378 0.33 0.080" />
    </joint>
      
    <link name="wheel_small_left">
        <visual>
            <geometry>
                <cylinder radius="0.080" length=".035"/>
            </geometry>
            <material name = "black"/>
        </visual>
    </link>

    <joint name="joint4" type="fixed">
        <parent link="base_footprint"/>
        <child link="wheel_small_left"/>
        <origin rpy="0 1.57075 1.57075" xyz= "-0.378 -.330 0.080"/>
    </joint>

    <link name="bottom_base">
        <visual>
            <geometry>
                <box size="1.0 .660 .070"/>
            </geometry>
            <material name = "grey">
                <color rgba="0.5 0.5 0.5 1"/>
            </material>
        </visual>
    </link>

    <!-- <joint name="joint5" type="fixed">
        <parent link="base_footprint"/>
        <child link="bottom_base"/>
        <origin rpy="0 0 0" xyz= "-0.088 0 0.105"/>
    </joint> -->
    
    <joint name="joint5" type="revolute">
        <axis xyz="0 0 1"/>
        <limit effort="1000.0" lower="-2.0944" upper="2.0944" velocity="0.5236"/>
        <parent link="base_footprint"/>
        <child link="bottom_base"/>
        <origin rpy="0 0 0" xyz= "-0.088 0 0.105"/>
    </joint>
      
    <link name="top_base">
        <visual>
            <geometry>
        <box size="0.9000 .660 .070"/> 
        </geometry>
            <material name = "grey"/>
        </visual>
    </link>

    <joint name="joint6" type="fixed">
        <parent link="base_footprint"/>
        <child link="top_base"/>
        <origin rpy="0 0 0" xyz= "-0.088 0 0.445"/>
    </joint>
      
    <link name="base_laser_link">
        <visual>
            <geometry>
                <box size="0.100 .100 .150"/> 
            </geometry>
            <material name = "blue">
                <color rgba="0 0 1 1"/>
            </material>
        </visual>
    </link>

    <joint name="joint7" type="fixed">
        <!-- <parent link="base_footprint"/> -->
        <parent link="bottom_base"/>
        <child link="base_laser_link"/>
        <!-- <origin rpy="0 0 0" xyz= "0.37 0 0.216"/> -->
        <origin rpy="0 0 0" xyz= "0.458 0 0.111"/>
    </joint> 

    <!-- <joint name="joint7" type="revolute">
        <axis xyz="0 0 1"/>
        <limit effort="1000.0" lower="-2.0944" upper="2.0944" velocity="0.5236"/>
        <parent link="base_footprint"/>
        <child link="base_laser_link"/>
        <origin rpy="0 0 0" xyz= "0.37 0 0.216"/>
    </joint> -->

    <link name="laser">
        <visual>
            <geometry>
                <box size="0.100 .100 .150"/> 
            </geometry>
            <material name = "blue">
                <color rgba="0 0 1 1"/>
            </material>
        </visual>
    </link>

    <joint name="joint8" type="fixed">
        <parent link="base_laser_link"/>
        <child link="laser"/>
        <origin rpy="3.14 0 0" xyz= "0 0 0"/>
    </joint>
    
</robot>
